Workbook
Name CFG_CompanyName: 'SETTINGS'!$B$5
Name CFG_CompanyShortName: 'SETTINGS'!$B$6
Name CFG_Tagline: 'SETTINGS'!$B$7
Name CFG_CompanyPhone: 'SETTINGS'!$B$8
Name CFG_CompanyAddress: 'SETTINGS'!$B$9
Name CFG_CustomerIDPrefix: 'SETTINGS'!$B$10
Name CFG_CustomerIDDigits: 'SETTINGS'!$B$11
Name CFG_Currency: 'SETTINGS'!$B$12
Name CFG_CurrencySymbol: 'SETTINGS'!$B$13
Name CFG_DefaultLanguage: 'SETTINGS'!$B$14
Name CFG_PrintLanguage: 'SETTINGS'!$B$15
Name CFG_CurrentMonth: 'SETTINGS'!$B$16
Name CFG_DateFormat: 'SETTINGS'!$B$17
Name CFG_DefaultPaymentMethod: 'SETTINGS'!$B$18
Name CFG_AllowNegativeBalance: 'SETTINGS'!$B$19
Name CFG_OverdueGraceDays: 'SETTINGS'!$B$20
Name CFG_OCRConfidenceThreshold: 'SETTINGS'!$B$21
Name CFG_WhatsAppCountryCode: 'SETTINGS'!$B$22
Name CFG_WhatsAppMessage: 'SETTINGS'!$B$23
Name CFG_PaperSize: 'SETTINGS'!$B$24
Name CFG_PrintOrientation: 'SETTINGS'!$B$25
Name CFG_WorkbookType: 'SETTINGS'!$B$26
Name L_CustStatus: 'LISTS'!$A$4:$A$7
Name L_PayStatus: 'LISTS'!$B$4:$B$6
Name L_Methods: 'LISTS'!$C$4:$C$8
Name L_YesNo: 'LISTS'!$D$4:$D$5
Name L_EventTypes: 'LISTS'!$E$4:$E$18
Name L_AssignStatus: 'LISTS'!$F$4:$F$7
Name L_Languages: 'LISTS'!$G$4:$G$5
Name L_PrintModes: 'LISTS'!$H$4:$H$10
Name L_PrintStatuses: 'LISTS'!$I$4:$I$9
Name L_PrintStatusLabels: 'LISTS'!$J$4:$J$9
Name L_SearchTypes: 'LISTS'!$K$4:$K$10
Name L_Months: 'LISTS'!$L$4:$L$147
Name L_MonthsAll: 'LISTS'!$M$4:$M$148
Name L_DueDaysAll: 'LISTS'!$N$4:$N$35
Name L_AreaCodes: OFFSET('LISTS'!$O$4,0,0,MAX(1,COUNTIF('LISTS'!$O$4:$O$306,"?*")),1)
Name L_AreaNamesAll: OFFSET('LISTS'!$P$4,0,0,MAX(1,COUNTIF('LISTS'!$P$4:$P$306,"?*")),1)
Name L_LocCodes: OFFSET('LISTS'!$Q$4,0,0,MAX(1,COUNTIF('LISTS'!$Q$4:$Q$306,"?*")),1)
Name L_LocCodesAll: OFFSET('LISTS'!$R$4,0,0,MAX(1,COUNTIF('LISTS'!$R$4:$R$306,"?*")),1)
Name L_Packages: OFFSET('LISTS'!$S$4,0,0,MAX(1,COUNTIF('LISTS'!$S$4:$S$306,"?*")),1)
Name L_CollectorIDs: OFFSET('LISTS'!$T$4,0,0,MAX(1,COUNTIF('LISTS'!$T$4:$T$306,"?*")),1)
Name L_CollectorNamesAll: OFFSET('LISTS'!$U$4,0,0,MAX(1,COUNTIF('LISTS'!$U$4:$U$306,"?*")),1)
Name L_CustomerIDs: OFFSET('LISTS'!$V$4,0,0,MAX(1,COUNTIF('LISTS'!$V$4:$V$306,"?*")),1)
Name DB_Month: 'DASHBOARD'!$C$2
Name PC_Mode: 'PRINT_CENTER'!$C$4
Name PC_Month: 'PRINT_CENTER'!$C$5
Name PC_Area: 'PRINT_CENTER'!$C$6
Name PC_Location: 'PRINT_CENTER'!$C$7
Name PC_Collector: 'PRINT_CENTER'!$C$8
Name PC_Status: 'PRINT_CENTER'!$C$9
Name PC_DueDate: 'PRINT_CENTER'!$C$10
Name PC_StatusEff: 'PRINT_CENTER'!$C$12
Name PC_Count: 'PRINT_CENTER'!$C$13
Name PC_Title: 'PRINT_CENTER'!$C$14
Name PC_TotalFee: 'PRINT_CENTER'!$C$15
Name PC_TotalPaid: 'PRINT_CENTER'!$C$16
Name PC_TotalBalance: 'PRINT_CENTER'!$C$17
Name PC_CustomIDs: 'PRINT_CENTER'!$F$4:$F$103
Name PC_CustomCount: 'PRINT_CENTER'!$G$4

Sheet HOME
B2: =CFG_CompanyName
B3: ISP CUSTOMER & RECOVERY MANAGEMENT SYSTEM
B4: =IF(CFG_WorkbookType<>"REAL DATA","*** DEMO WORKBOOK - SAMPLE DATA ONLY - NOT REAL CUSTOMERS ***","")
B6: Current Month: | C6: =CFG_CurrentMonth&" ("&IFERROR(TEXT(DATE(LEFT(CFG_CurrentMonth,4),MID(CFG_CurrentMonth,6,2),1),"mmmm yyyy"),"not set")&")"
B7: Customers (Active / Total): | C7: =COUNTIF(tblCustomers[Customer Status],"Active")&" / "&(COUNTIF(tblCustomers[Customer ID],"?*"))
B8: Next Customer ID: | C8: =CFG_CustomerIDPrefix&"-"&TEXT(IFERROR(AGGREGATE(14,6,--MID(tblCustomers[Customer ID],LEN(CFG_CustomerIDPrefix)+2,10)/(LEFT(tblCustomers[Customer ID],LEN(CFG_CustomerIDPrefix)+1)=CFG_CustomerIDPrefix&"-"),1),0)+1,REPT("0",CFG_CustomerIDDigits))
B9: Open verification items: | C9: =COUNTIF(tblVerify[Status],"Open")
B10: Customers with data problems: | C10: =COUNTIF(tblCustomers[Data Check],"?*")
B12: GO TO | E12: MONTHLY WORKFLOW
B13: ► Dashboard | E13: 1. Double-click CityLinks.bat (menu program). Close this workbook in Excel first.
B14: ► Customer Master | E14: 2. Menu 1: Select / generate the month (GENERATE NEW MONTH). A backup is made first.
B15: ► Add Customer | E15: 3. Menu: Assign customers to collectors (by area / street / customer) if needed.
B16: ► Monthly Recovery | E16: 4. PRINT_CENTER: choose Area / Street / Collector / Status -> print PRINT_SHEET,
B17: ► Payment Entry | E17: or use the menu to save a PDF recovery list.
B18: ► Payments | E18: 5. Recovery boy collects cash and returns the signed list.
B19: ► Print Center | E19: 6. Enter payments: menu 'Record payment' or 'Quick recovery entry' (whole list at once).
B20: ► Customer History | E20: 7. Enter the cash he handed over in CASH_RECONCILIATION (Actual Cash Submitted).
B21: ► Customer Statement | E21: 8. DASHBOARD updates automatically.
B22: ► Pending Recovery | E22: 9. CUSTOMER_HISTORY: type any Customer ID (e.g. CL-0025) to see the complete history.
B23: ► Cash Reconciliation | E23: 10. Menu 'Customer statement PDF' -> PDF saved in exports/statements.
B24: ► Recovery Assignments | E24: 11. Menu shows the WhatsApp link - attach the PDF manually and send.
B25: ► Reports
B26: ► Monthly Archive
B27: ► Connection History | E27: CELL COLOURS
B28: ► Areas | F28: Yellow = you can type / choose here
B29: ► Location Codes | F29: Grey = calculated by formula (do not type)
B30: ► Packages | F30: Light blue = generated by the system (IDs, monthly snapshots)
B31: ► Collectors
B32: ► Verification Queue | E32: SAFETY RULES
B33: ► Settings | E33: • Never delete customers, bills or payments. Use Customer Status / Voided instead.
E34: • Customer ID never changes. VLAN / fee / area changes are recorded in CUSTOMER_EVENTS.
E35: • Backups are created automatically in the backups folder before major operations.
E36: • Handwritten data is never guessed - unclear values go to VERIFICATION_QUEUE.

Sheet DASHBOARD
A1: =CFG_CompanyName&" - RECOVERY DASHBOARD" | N1: ◄ HOME
A2: Month (YYYY-MM): | C2: =CFG_CurrentMonth | D2: =IFERROR(TEXT(DATE(LEFT(DB_Month,4),MID(DB_Month,6,2),1),"mmmm yyyy"),"Select month") | F2: =IF(CFG_WorkbookType<>"REAL DATA","DEMO WORKBOOK - SAMPLE DATA ONLY","")
A3: All figures are calculated from the workbook data. Nothing is typed by hand.
A5: CUSTOMERS | E5: SELECTED MONTH | I5: PAYMENT STATUS | M5: CASH
A6: Total Customers | E6: Customers Billed | I6: Paid Customers | M6: Today's Collection
A7: =COUNTIF(tblCustomers[Customer ID],"?*") | E7: =COUNTIF(tblBilling[Month],DB_Month) | I7: =COUNTIFS(tblBilling[Month],DB_Month,tblBilling[Payment Status],"PAID") | M7: =SUMIFS(tblPayments[Amount],tblPayments[Payment Date],TODAY(),tblPayments[Voided],"<>Yes")
A8: Active Customers | E8: Monthly Billing | I8: Partial Customers | M8: Current Month Collection
A9: =COUNTIF(tblCustomers[Customer Status],"Active") | E9: =SUMIFS(tblBilling[Monthly Fee],tblBilling[Month],DB_Month) | I9: =COUNTIFS(tblBilling[Month],DB_Month,tblBilling[Payment Status],"PARTIAL") | M9: =IFERROR(SUMIFS(tblPayments[Amount],tblPayments[Payment Date],">="&DATE(LEFT(DB_Month,4),MID(DB_Month,6,2),1),tblPayments[Payment Date],"<="&EOMONTH(DATE(LEFT(DB_Month,4),MID(DB_Month,6,2),1),0),tblPayments[Voided],"<>Yes"),0)
A10: Suspended | E10: Total Recovered | I10: Total Partial (Balance) | M10: Outstanding Balance (All Months)
A11: =COUNTIF(tblCustomers[Customer Status],"Suspended") | E11: =SUMIFS(tblBilling[Amount Paid],tblBilling[Month],DB_Month) | I11: =SUMIFS(tblBilling[Balance],tblBilling[Month],DB_Month,tblBilling[Payment Status],"PARTIAL") | M11: =SUM(tblBilling[Balance])
A12: Disconnected Customers | E12: Total Pending (Balance) | I12: Pending Customers | M12: Cash Difference (Month)
A13: =COUNTIF(tblCustomers[Customer Status],"Disconnected") | E13: =SUMIFS(tblBilling[Balance],tblBilling[Month],DB_Month) | I13: =COUNTIFS(tblBilling[Month],DB_Month,tblBilling[Payment Status],"PENDING") | M13: =SUMIFS(tblCash[Cash Difference],tblCash[Month],DB_Month)
A14: On Hold | E14: Recovery Percentage | I14: Overdue Customers | M14: Collectors Not Submitted
A15: =COUNTIF(tblCustomers[Customer Status],"On Hold") | E15: =IF(SUMIFS(tblBilling[Monthly Fee],tblBilling[Month],DB_Month)=0,0,SUMIFS(tblBilling[Amount Paid],tblBilling[Month],DB_Month)/SUMIFS(tblBilling[Monthly Fee],tblBilling[Month],DB_Month)) | I15: =COUNTIFS(tblBilling[Month],DB_Month,tblBilling[Overdue],"OVERDUE") | M15: =COUNTIFS(tblCash[Month],DB_Month,tblCash[Reconciliation Status],"NOT SUBMITTED")
A16: Current Month Collection = all payments received (by payment date) during the selected calendar month, for any bill.
A18: AREA-WISE RECOVERY (selected month)
A19: Area | B19: Customers | C19: Active Customers | D19: Billed | E19: Monthly Billing | F19: Recovered | G19: Pending (Balance) | H19: Paid | I19: Partial | J19: Pending | K19: Recovery %
A20: =IFERROR(INDEX(tblAreas[Area Name],1)&"","") | B20: =IF($A20="","",COUNTIF(tblCustomers[Area],$A20)) | C20: =IF($A20="","",COUNTIFS(tblCustomers[Area],$A20,tblCustomers[Customer Status],"Active")) | D20: =IF($A20="","",COUNTIFS(tblBilling[Month],DB_Month,tblBilling[Area],$A20)) | E20: =IF($A20="","",SUMIFS(tblBilling[Monthly Fee],tblBilling[Month],DB_Month,tblBilling[Area],$A20)) | F20: =IF($A20="","",SUMIFS(tblBilling[Amount Paid],tblBilling[Month],DB_Month,tblBilling[Area],$A20)) | G20: =IF($A20="","",SUMIFS(tblBilling[Balance],tblBilling[Month],DB_Month,tblBilling[Area],$A20)) | H20: =IF($A20="","",COUNTIFS(tblBilling[Month],DB_Month,tblBilling[Area],$A20,tblBilling[Payment Status],"PAID")) | I20: =IF($A20="","",COUNTIFS(tblBilling[Month],DB_Month,tblBilling[Area],$A20,tblBilling[Payment Status],"PARTIAL")) | J20: =IF($A20="","",COUNTIFS(tblBilling[Month],DB_Month,tblBilling[Area],$A20,tblBilling[Payment Status],"PENDING")) | K20: =IF(OR($A20="",N(E20)=0),"",F20/E20)
A21: =IFERROR(INDEX(tblAreas[Area Name],2)&"","") | B21: =IF($A21="","",COUNTIF(tblCustomers[Area],$A21)) | C21: =IF($A21="","",COUNTIFS(tblCustomers[Area],$A21,tblCustomers[Customer Status],"Active")) | D21: =IF($A21="","",COUNTIFS(tblBilling[Month],DB_Month,tblBilling[Area],$A21)) | E21: =IF($A21="","",SUMIFS(tblBilling[Monthly Fee],tblBilling[Month],DB_Month,tblBilling[Area],$A21)) | F21: =IF($A21="","",SUMIFS(tblBilling[Amount Paid],tblBilling[Month],DB_Month,tblBilling[Area],$A21)) | G21: =IF($A21="","",SUMIFS(tblBilling[Balance],tblBilling[Month],DB_Month,tblBilling[Area],$A21)) | H21: =IF($A21="","",COUNTIFS(tblBilling[Month],DB_Month,tblBilling[Area],$A21,tblBilling[Payment Status],"PAID")) | I21: =IF($A21="","",COUNTIFS(tblBilling[Month],DB_Month,tblBilling[Area],$A21,tblBilling[Payment Status],"PARTIAL")) | J21: =IF($A21="","",COUNTIFS(tblBilling[Month],DB_Month,tblBilling[Area],$A21,tblBilling[Payment Status],"PENDING")) | K21: =IF(OR($A21="",N(E21)=0),"",F21/E21)
A22: =IFERROR(INDEX(tblAreas[Area Name],3)&"","") | B22: =IF($A22="","",COUNTIF(tblCustomers[Area],$A22)) | C22: =IF($A22="","",COUNTIFS(tblCustomers[Area],$A22,tblCustomers[Customer Status],"Active")) | D22: =IF($A22="","",COUNTIFS(tblBilling[Month],DB_Month,tblBilling[Area],$A22)) | E22: =IF($A22="","",SUMIFS(tblBilling[Monthly Fee],tblBilling[Month],DB_Month,tblBilling[Area],$A22)) | F22: =IF($A22="","",SUMIFS(tblBilling[Amount Paid],tblBilling[Month],DB_Month,tblBilling[Area],$A22)) | G22: =IF($A22="","",SUMIFS(tblBilling[Balance],tblBilling[Month],DB_Month,tblBilling[Area],$A22)) | H22: =IF($A22="","",COUNTIFS(tblBilling[Month],DB_Month,tblBilling[Area],$A22,tblBilling[Payment Status],"PAID")) | I22: =IF($A22="","",COUNTIFS(tblBilling[Month],DB_Month,tblBilling[Area],$A22,tblBilling[Payment Status],"PARTIAL")) | J22: =IF($A22="","",COUNTIFS(tblBilling[Month],DB_Month,tblBilling[Area],$A22,tblBilling[Payment Status],"PENDING")) | K22: =IF(OR($A22="",N(E22)=0),"",F22/E22)
A23: =IFERROR(INDEX(tblAreas[Area Name],4)&"","") | B23: =IF($A23="","",COUNTIF(tblCustomers[Area],$A23)) | C23: =IF($A23="","",COUNTIFS(tblCustomers[Area],$A23,tblCustomers[Customer Status],"Active")) | D23: =IF($A23="","",COUNTIFS(tblBilling[Month],DB_Month,tblBilling[Area],$A23)) | E23: =IF($A23="","",SUMIFS(tblBilling[Monthly Fee],tblBilling[Month],DB_Month,tblBilling[Area],$A23)) | F23: =IF($A23="","",SUMIFS(tblBilling[Amount Paid],tblBilling[Month],DB_Month,tblBilling[Area],$A23)) | G23: =IF($A23="","",SUMIFS(tblBilling[Balance],tblBilling[Month],DB_Month,tblBilling[Area],$A23)) | H23: =IF($A23="","",COUNTIFS(tblBilling[Month],DB_Month,tblBilling[Area],$A23,tblBilling[Payment Status],"PAID")) | I23: =IF($A23="","",COUNTIFS(tblBilling[Month],DB_Month,tblBilling[Area],$A23,tblBilling[Payment Status],"PARTIAL")) | J23: =IF($A23="","",COUNTIFS(tblBilling[Month],DB_Month,tblBilling[Area],$A23,tblBilling[Payment Status],"PENDING")) | K23: =IF(OR($A23="",N(E23)=0),"",F23/E23)
A24: =IFERROR(INDEX(tblAreas[Area Name],5)&"","") | B24: =IF($A24="","",COUNTIF(tblCustomers[Area],$A24)) | C24: =IF($A24="","",COUNTIFS(tblCustomers[Area],$A24,tblCustomers[Customer Status],"Active")) | D24: =IF($A24="","",COUNTIFS(tblBilling[Month],DB_Month,tblBilling[Area],$A24)) | E24: =IF($A24="","",SUMIFS(tblBilling[Monthly Fee],tblBilling[Month],DB_Month,tblBilling[Area],$A24)) | F24: =IF($A24="","",SUMIFS(tblBilling[Amount Paid],tblBilling[Month],DB_Month,tblBilling[Area],$A24)) | G24: =IF($A24="","",SUMIFS(tblBilling[Balance],tblBilling[Month],DB_Month,tblBilling[Area],$A24)) | H24: =IF($A24="","",COUNTIFS(tblBilling[Month],DB_Month,tblBilling[Area],$A24,tblBilling[Payment Status],"PAID")) | I24: =IF($A24="","",COUNTIFS(tblBilling[Month],DB_Month,tblBilling[Area],$A24,tblBilling[Payment Status],"PARTIAL")) | J24: =IF($A24="","",COUNTIFS(tblBilling[Month],DB_Month,tblBilling[Area],$A24,tblBilling[Payment Status],"PENDING")) | K24: =IF(OR($A24="",N(E24)=0),"",F24/E24)
A25: =IFERROR(INDEX(tblAreas[Area Name],6)&"","") | B25: =IF($A25="","",COUNTIF(tblCustomers[Area],$A25)) | C25: =IF($A25="","",COUNTIFS(tblCustomers[Area],$A25,tblCustomers[Customer Status],"Active")) | D25: =IF($A25="","",COUNTIFS(tblBilling[Month],DB_Month,tblBilling[Area],$A25)) | E25: =IF($A25="","",SUMIFS(tblBilling[Monthly Fee],tblBilling[Month],DB_Month,tblBilling[Area],$A25)) | F25: =IF($A25="","",SUMIFS(tblBilling[Amount Paid],tblBilling[Month],DB_Month,tblBilling[Area],$A25)) | G25: =IF($A25="","",SUMIFS(tblBilling[Balance],tblBilling[Month],DB_Month,tblBilling[Area],$A25)) | H25: =IF($A25="","",COUNTIFS(tblBilling[Month],DB_Month,tblBilling[Area],$A25,tblBilling[Payment Status],"PAID")) | I25: =IF($A25="","",COUNTIFS(tblBilling[Month],DB_Month,tblBilling[Area],$A25,tblBilling[Payment Status],"PARTIAL")) | J25: =IF($A25="","",COUNTIFS(tblBilling[Month],DB_Month,tblBilling[Area],$A25,tblBilling[Payment Status],"PENDING")) | K25: =IF(OR($A25="",N(E25)=0),"",F25/E25)
A26: =IFERROR(INDEX(tblAreas[Area Name],7)&"","") | B26: =IF($A26="","",COUNTIF(tblCustomers[Area],$A26)) | C26: =IF($A26="","",COUNTIFS(tblCustomers[Area],$A26,tblCustomers[Customer Status],"Active")) | D26: =IF($A26="","",COUNTIFS(tblBilling[Month],DB_Month,tblBilling[Area],$A26)) | E26: =IF($A26="","",SUMIFS(tblBilling[Monthly Fee],tblBilling[Month],DB_Month,tblBilling[Area],$A26)) | F26: =IF($A26="","",SUMIFS(tblBilling[Amount Paid],tblBilling[Month],DB_Month,tblBilling[Area],$A26)) | G26: =IF($A26="","",SUMIFS(tblBilling[Balance],tblBilling[Month],DB_Month,tblBilling[Area],$A26)) | H26: =IF($A26="","",COUNTIFS(tblBilling[Month],DB_Month,tblBilling[Area],$A26,tblBilling[Payment Status],"PAID")) | I26: =IF($A26="","",COUNTIFS(tblBilling[Month],DB_Month,tblBilling[Area],$A26,tblBilling[Payment Status],"PARTIAL")) | J26: =IF($A26="","",COUNTIFS(tblBilling[Month],DB_Month,tblBilling[Area],$A26,tblBilling[Payment Status],"PENDING")) | K26: =IF(OR($A26="",N(E26)=0),"",F26/E26)
A27: =IFERROR(INDEX(tblAreas[Area Name],8)&"","") | B27: =IF($A27="","",COUNTIF(tblCustomers[Area],$A27)) | C27: =IF($A27="","",COUNTIFS(tblCustomers[Area],$A27,tblCustomers[Customer Status],"Active")) | D27: =IF($A27="","",COUNTIFS(tblBilling[Month],DB_Month,tblBilling[Area],$A27)) | E27: =IF($A27="","",SUMIFS(tblBilling[Monthly Fee],tblBilling[Month],DB_Month,tblBilling[Area],$A27)) | F27: =IF($A27="","",SUMIFS(tblBilling[Amount Paid],tblBilling[Month],DB_Month,tblBilling[Area],$A27)) | G27: =IF($A27="","",SUMIFS(tblBilling[Balance],tblBilling[Month],DB_Month,tblBilling[Area],$A27)) | H27: =IF($A27="","",COUNTIFS(tblBilling[Month],DB_Month,tblBilling[Area],$A27,tblBilling[Payment Status],"PAID")) | I27: =IF($A27="","",COUNTIFS(tblBilling[Month],DB_Month,tblBilling[Area],$A27,tblBilling[Payment Status],"PARTIAL")) | J27: =IF($A27="","",COUNTIFS(tblBilling[Month],DB_Month,tblBilling[Area],$A27,tblBilling[Payment Status],"PENDING")) | K27: =IF(OR($A27="",N(E27)=0),"",F27/E27)
A28: =IFERROR(INDEX(tblAreas[Area Name],9)&"","") | B28: =IF($A28="","",COUNTIF(tblCustomers[Area],$A28)) | C28: =IF($A28="","",COUNTIFS(tblCustomers[Area],$A28,tblCustomers[Customer Status],"Active")) | D28: =IF($A28="","",COUNTIFS(tblBilling[Month],DB_Month,tblBilling[Area],$A28)) | E28: =IF($A28="","",SUMIFS(tblBilling[Monthly Fee],tblBilling[Month],DB_Month,tblBilling[Area],$A28)) | F28: =IF($A28="","",SUMIFS(tblBilling[Amount Paid],tblBilling[Month],DB_Month,tblBilling[Area],$A28)) | G28: =IF($A28="","",SUMIFS(tblBilling[Balance],tblBilling[Month],DB_Month,tblBilling[Area],$A28)) | H28: =IF($A28="","",COUNTIFS(tblBilling[Month],DB_Month,tblBilling[Area],$A28,tblBilling[Payment Status],"PAID")) | I28: =IF($A28="","",COUNTIFS(tblBilling[Month],DB_Month,tblBilling[Area],$A28,tblBilling[Payment Status],"PARTIAL")) | J28: =IF($A28="","",COUNTIFS(tblBilling[Month],DB_Month,tblBilling[Area],$A28,tblBilling[Payment Status],"PENDING")) | K28: =IF(OR($A28="",N(E28)=0),"",F28/E28)
A29: =IFERROR(INDEX(tblAreas[Area Name],10)&"","") | B29: =IF($A29="","",COUNTIF(tblCustomers[Area],$A29)) | C29: =IF($A29="","",COUNTIFS(tblCustomers[Area],$A29,tblCustomers[Customer Status],"Active")) | D29: =IF($A29="","",COUNTIFS(tblBilling[Month],DB_Month,tblBilling[Area],$A29)) | E29: =IF($A29="","",SUMIFS(tblBilling[Monthly Fee],tblBilling[Month],DB_Month,tblBilling[Area],$A29)) | F29: =IF($A29="","",SUMIFS(tblBilling[Amount Paid],tblBilling[Month],DB_Month,tblBilling[Area],$A29)) | G29: =IF($A29="","",SUMIFS(tblBilling[Balance],tblBilling[Month],DB_Month,tblBilling[Area],$A29)) | H29: =IF($A29="","",COUNTIFS(tblBilling[Month],DB_Month,tblBilling[Area],$A29,tblBilling[Payment Status],"PAID")) | I29: =IF($A29="","",COUNTIFS(tblBilling[Month],DB_Month,tblBilling[Area],$A29,tblBilling[Payment Status],"PARTIAL")) | J29: =IF($A29="","",COUNTIFS(tblBilling[Month],DB_Month,tblBilling[Area],$A29,tblBilling[Payment Status],"PENDING")) | K29: =IF(OR($A29="",N(E29)=0),"",F29/E29)
A30: =IFERROR(INDEX(tblAreas[Area Name],11)&"","") | B30: =IF($A30="","",COUNTIF(tblCustomers[Area],$A30)) | C30: =IF($A30="","",COUNTIFS(tblCustomers[Area],$A30,tblCustomers[Customer Status],"Active")) | D30: =IF($A30="","",COUNTIFS(tblBilling[Month],DB_Month,tblBilling[Area],$A30)) | E30: =IF($A30="","",SUMIFS(tblBilling[Monthly Fee],tblBilling[Month],DB_Month,tblBilling[Area],$A30)) | F30: =IF($A30="","",SUMIFS(tblBilling[Amount Paid],tblBilling[Month],DB_Month,tblBilling[Area],$A30)) | G30: =IF($A30="","",SUMIFS(tblBilling[Balance],tblBilling[Month],DB_Month,tblBilling[Area],$A30)) | H30: =IF($A30="","",COUNTIFS(tblBilling[Month],DB_Month,tblBilling[Area],$A30,tblBilling[Payment Status],"PAID")) | I30: =IF($A30="","",COUNTIFS(tblBilling[Month],DB_Month,tblBilling[Area],$A30,tblBilling[Payment Status],"PARTIAL")) | J30: =IF($A30="","",COUNTIFS(tblBilling[Month],DB_Month,tblBilling[Area],$A30,tblBilling[Payment Status],"PENDING")) | K30: =IF(OR($A30="",N(E30)=0),"",F30/E30)
A31: =IFERROR(INDEX(tblAreas[Area Name],12)&"","") | B31: =IF($A31="","",COUNTIF(tblCustomers[Area],$A31)) | C31: =IF($A31="","",COUNTIFS(tblCustomers[Area],$A31,tblCustomers[Customer Status],"Active")) | D31: =IF($A31="","",COUNTIFS(tblBilling[Month],DB_Month,tblBilling[Area],$A31)) | E31: =IF($A31="","",SUMIFS(tblBilling[Monthly Fee],tblBilling[Month],DB_Month,tblBilling[Area],$A31)) | F31: =IF($A31="","",SUMIFS(tblBilling[Amount Paid],tblBilling[Month],DB_Month,tblBilling[Area],$A31)) | G31: =IF($A31="","",SUMIFS(tblBilling[Balance],tblBilling[Month],DB_Month,tblBilling[Area],$A31)) | H31: =IF($A31="","",COUNTIFS(tblBilling[Month],DB_Month,tblBilling[Area],$A31,tblBilling[Payment Status],"PAID")) | I31: =IF($A31="","",COUNTIFS(tblBilling[Month],DB_Month,tblBilling[Area],$A31,tblBilling[Payment Status],"PARTIAL")) | J31: =IF($A31="","",COUNTIFS(tblBilling[Month],DB_Month,tblBilling[Area],$A31,tblBilling[Payment Status],"PENDING")) | K31: =IF(OR($A31="",N(E31)=0),"",F31/E31)
A32: =IFERROR(INDEX(tblAreas[Area Name],13)&"","") | B32: =IF($A32="","",COUNTIF(tblCustomers[Area],$A32)) | C32: =IF($A32="","",COUNTIFS(tblCustomers[Area],$A32,tblCustomers[Customer Status],"Active")) | D32: =IF($A32="","",COUNTIFS(tblBilling[Month],DB_Month,tblBilling[Area],$A32)) | E32: =IF($A32="","",SUMIFS(tblBilling[Monthly Fee],tblBilling[Month],DB_Month,tblBilling[Area],$A32)) | F32: =IF($A32="","",SUMIFS(tblBilling[Amount Paid],tblBilling[Month],DB_Month,tblBilling[Area],$A32)) | G32: =IF($A32="","",SUMIFS(tblBilling[Balance],tblBilling[Month],DB_Month,tblBilling[Area],$A32)) | H32: =IF($A32="","",COUNTIFS(tblBilling[Month],DB_Month,tblBilling[Area],$A32,tblBilling[Payment Status],"PAID")) | I32: =IF($A32="","",COUNTIFS(tblBilling[Month],DB_Month,tblBilling[Area],$A32,tblBilling[Payment Status],"PARTIAL")) | J32: =IF($A32="","",COUNTIFS(tblBilling[Month],DB_Month,tblBilling[Area],$A32,tblBilling[Payment Status],"PENDING")) | K32: =IF(OR($A32="",N(E32)=0),"",F32/E32)
A33: =IFERROR(INDEX(tblAreas[Area Name],14)&"","") | B33: =IF($A33="","",COUNTIF(tblCustomers[Area],$A33)) | C33: =IF($A33="","",COUNTIFS(tblCustomers[Area],$A33,tblCustomers[Customer Status],"Active")) | D33: =IF($A33="","",COUNTIFS(tblBilling[Month],DB_Month,tblBilling[Area],$A33)) | E33: =IF($A33="","",SUMIFS(tblBilling[Monthly Fee],tblBilling[Month],DB_Month,tblBilling[Area],$A33)) | F33: =IF($A33="","",SUMIFS(tblBilling[Amount Paid],tblBilling[Month],DB_Month,tblBilling[Area],$A33)) | G33: =IF($A33="","",SUMIFS(tblBilling[Balance],tblBilling[Month],DB_Month,tblBilling[Area],$A33)) | H33: =IF($A33="","",COUNTIFS(tblBilling[Month],DB_Month,tblBilling[Area],$A33,tblBilling[Payment Status],"PAID")) | I33: =IF($A33="","",COUNTIFS(tblBilling[Month],DB_Month,tblBilling[Area],$A33,tblBilling[Payment Status],"PARTIAL")) | J33: =IF($A33="","",COUNTIFS(tblBilling[Month],DB_Month,tblBilling[Area],$A33,tblBilling[Payment Status],"PENDING")) | K33: =IF(OR($A33="",N(E33)=0),"",F33/E33)
A34: =IFERROR(INDEX(tblAreas[Area Name],15)&"","") | B34: =IF($A34="","",COUNTIF(tblCustomers[Area],$A34)) | C34: =IF($A34="","",COUNTIFS(tblCustomers[Area],$A34,tblCustomers[Customer Status],"Active")) | D34: =IF($A34="","",COUNTIFS(tblBilling[Month],DB_Month,tblBilling[Area],$A34)) | E34: =IF($A34="","",SUMIFS(tblBilling[Monthly Fee],tblBilling[Month],DB_Month,tblBilling[Area],$A34)) | F34: =IF($A34="","",SUMIFS(tblBilling[Amount Paid],tblBilling[Month],DB_Month,tblBilling[Area],$A34)) | G34: =IF($A34="","",SUMIFS(tblBilling[Balance],tblBilling[Month],DB_Month,tblBilling[Area],$A34)) | H34: =IF($A34="","",COUNTIFS(tblBilling[Month],DB_Month,tblBilling[Area],$A34,tblBilling[Payment Status],"PAID")) | I34: =IF($A34="","",COUNTIFS(tblBilling[Month],DB_Month,tblBilling[Area],$A34,tblBilling[Payment Status],"PARTIAL")) | J34: =IF($A34="","",COUNTIFS(tblBilling[Month],DB_Month,tblBilling[Area],$A34,tblBilling[Payment Status],"PENDING")) | K34: =IF(OR($A34="",N(E34)=0),"",F34/E34)
A35: =IFERROR(INDEX(tblAreas[Area Name],16)&"","") | B35: =IF($A35="","",COUNTIF(tblCustomers[Area],$A35)) | C35: =IF($A35="","",COUNTIFS(tblCustomers[Area],$A35,tblCustomers[Customer Status],"Active")) | D35: =IF($A35="","",COUNTIFS(tblBilling[Month],DB_Month,tblBilling[Area],$A35)) | E35: =IF($A35="","",SUMIFS(tblBilling[Monthly Fee],tblBilling[Month],DB_Month,tblBilling[Area],$A35)) | F35: =IF($A35="","",SUMIFS(tblBilling[Amount Paid],tblBilling[Month],DB_Month,tblBilling[Area],$A35)) | G35: =IF($A35="","",SUMIFS(tblBilling[Balance],tblBilling[Month],DB_Month,tblBilling[Area],$A35)) | H35: =IF($A35="","",COUNTIFS(tblBilling[Month],DB_Month,tblBilling[Area],$A35,tblBilling[Payment Status],"PAID")) | I35: =IF($A35="","",COUNTIFS(tblBilling[Month],DB_Month,tblBilling[Area],$A35,tblBilling[Payment Status],"PARTIAL")) | J35: =IF($A35="","",COUNTIFS(tblBilling[Month],DB_Month,tblBilling[Area],$A35,tblBilling[Payment Status],"PENDING")) | K35: =IF(OR($A35="",N(E35)=0),"",F35/E35)
A36: =IFERROR(INDEX(tblAreas[Area Name],17)&"","") | B36: =IF($A36="","",COUNTIF(tblCustomers[Area],$A36)) | C36: =IF($A36="","",COUNTIFS(tblCustomers[Area],$A36,tblCustomers[Customer Status],"Active")) | D36: =IF($A36="","",COUNTIFS(tblBilling[Month],DB_Month,tblBilling[Area],$A36)) | E36: =IF($A36="","",SUMIFS(tblBilling[Monthly Fee],tblBilling[Month],DB_Month,tblBilling[Area],$A36)) | F36: =IF($A36="","",SUMIFS(tblBilling[Amount Paid],tblBilling[Month],DB_Month,tblBilling[Area],$A36)) | G36: =IF($A36="","",SUMIFS(tblBilling[Balance],tblBilling[Month],DB_Month,tblBilling[Area],$A36)) | H36: =IF($A36="","",COUNTIFS(tblBilling[Month],DB_Month,tblBilling[Area],$A36,tblBilling[Payment Status],"PAID")) | I36: =IF($A36="","",COUNTIFS(tblBilling[Month],DB_Month,tblBilling[Area],$A36,tblBilling[Payment Status],"PARTIAL")) | J36: =IF($A36="","",COUNTIFS(tblBilling[Month],DB_Month,tblBilling[Area],$A36,tblBilling[Payment Status],"PENDING")) | K36: =IF(OR($A36="",N(E36)=0),"",F36/E36)
A37: =IFERROR(INDEX(tblAreas[Area Name],18)&"","") | B37: =IF($A37="","",COUNTIF(tblCustomers[Area],$A37)) | C37: =IF($A37="","",COUNTIFS(tblCustomers[Area],$A37,tblCustomers[Customer Status],"Active")) | D37: =IF($A37="","",COUNTIFS(tblBilling[Month],DB_Month,tblBilling[Area],$A37)) | E37: =IF($A37="","",SUMIFS(tblBilling[Monthly Fee],tblBilling[Month],DB_Month,tblBilling[Area],$A37)) | F37: =IF($A37="","",SUMIFS(tblBilling[Amount Paid],tblBilling[Month],DB_Month,tblBilling[Area],$A37)) | G37: =IF($A37="","",SUMIFS(tblBilling[Balance],tblBilling[Month],DB_Month,tblBilling[Area],$A37)) | H37: =IF($A37="","",COUNTIFS(tblBilling[Month],DB_Month,tblBilling[Area],$A37,tblBilling[Payment Status],"PAID")) | I37: =IF($A37="","",COUNTIFS(tblBilling[Month],DB_Month,tblBilling[Area],$A37,tblBilling[Payment Status],"PARTIAL")) | J37: =IF($A37="","",COUNTIFS(tblBilling[Month],DB_Month,tblBilling[Area],$A37,tblBilling[Payment Status],"PENDING")) | K37: =IF(OR($A37="",N(E37)=0),"",F37/E37)
A38: =IFERROR(INDEX(tblAreas[Area Name],19)&"","") | B38: =IF($A38="","",COUNTIF(tblCustomers[Area],$A38)) | C38: =IF($A38="","",COUNTIFS(tblCustomers[Area],$A38,tblCustomers[Customer Status],"Active")) | D38: =IF($A38="","",COUNTIFS(tblBilling[Month],DB_Month,tblBilling[Area],$A38)) | E38: =IF($A38="","",SUMIFS(tblBilling[Monthly Fee],tblBilling[Month],DB_Month,tblBilling[Area],$A38)) | F38: =IF($A38="","",SUMIFS(tblBilling[Amount Paid],tblBilling[Month],DB_Month,tblBilling[Area],$A38)) | G38: =IF($A38="","",SUMIFS(tblBilling[Balance],tblBilling[Month],DB_Month,tblBilling[Area],$A38)) | H38: =IF($A38="","",COUNTIFS(tblBilling[Month],DB_Month,tblBilling[Area],$A38,tblBilling[Payment Status],"PAID")) | I38: =IF($A38="","",COUNTIFS(tblBilling[Month],DB_Month,tblBilling[Area],$A38,tblBilling[Payment Status],"PARTIAL")) | J38: =IF($A38="","",COUNTIFS(tblBilling[Month],DB_Month,tblBilling[Area],$A38,tblBilling[Payment Status],"PENDING")) | K38: =IF(OR($A38="",N(E38)=0),"",F38/E38)
A39: =IFERROR(INDEX(tblAreas[Area Name],20)&"","") | B39: =IF($A39="","",COUNTIF(tblCustomers[Area],$A39)) | C39: =IF($A39="","",COUNTIFS(tblCustomers[Area],$A39,tblCustomers[Customer Status],"Active")) | D39: =IF($A39="","",COUNTIFS(tblBilling[Month],DB_Month,tblBilling[Area],$A39)) | E39: =IF($A39="","",SUMIFS(tblBilling[Monthly Fee],tblBilling[Month],DB_Month,tblBilling[Area],$A39)) | F39: =IF($A39="","",SUMIFS(tblBilling[Amount Paid],tblBilling[Month],DB_Month,tblBilling[Area],$A39)) | G39: =IF($A39="","",SUMIFS(tblBilling[Balance],tblBilling[Month],DB_Month,tblBilling[Area],$A39)) | H39: =IF($A39="","",COUNTIFS(tblBilling[Month],DB_Month,tblBilling[Area],$A39,tblBilling[Payment Status],"PAID")) | I39: =IF($A39="","",COUNTIFS(tblBilling[Month],DB_Month,tblBilling[Area],$A39,tblBilling[Payment Status],"PARTIAL")) | J39: =IF($A39="","",COUNTIFS(tblBilling[Month],DB_Month,tblBilling[Area],$A39,tblBilling[Payment Status],"PENDING")) | K39: =IF(OR($A39="",N(E39)=0),"",F39/E39)
A40: =IFERROR(INDEX(tblAreas[Area Name],21)&"","") | B40: =IF($A40="","",COUNTIF(tblCustomers[Area],$A40)) | C40: =IF($A40="","",COUNTIFS(tblCustomers[Area],$A40,tblCustomers[Customer Status],"Active")) | D40: =IF($A40="","",COUNTIFS(tblBilling[Month],DB_Month,tblBilling[Area],$A40)) | E40: =IF($A40="","",SUMIFS(tblBilling[Monthly Fee],tblBilling[Month],DB_Month,tblBilling[Area],$A40)) | F40: =IF($A40="","",SUMIFS(tblBilling[Amount Paid],tblBilling[Month],DB_Month,tblBilling[Area],$A40)) | G40: =IF($A40="","",SUMIFS(tblBilling[Balance],tblBilling[Month],DB_Month,tblBilling[Area],$A40)) | H40: =IF($A40="","",COUNTIFS(tblBilling[Month],DB_Month,tblBilling[Area],$A40,tblBilling[Payment Status],"PAID")) | I40: =IF($A40="","",COUNTIFS(tblBilling[Month],DB_Month,tblBilling[Area],$A40,tblBilling[Payment Status],"PARTIAL")) | J40: =IF($A40="","",COUNTIFS(tblBilling[Month],DB_Month,tblBilling[Area],$A40,tblBilling[Payment Status],"PENDING")) | K40: =IF(OR($A40="",N(E40)=0),"",F40/E40)
A41: =IFERROR(INDEX(tblAreas[Area Name],22)&"","") | B41: =IF($A41="","",COUNTIF(tblCustomers[Area],$A41)) | C41: =IF($A41="","",COUNTIFS(tblCustomers[Area],$A41,tblCustomers[Customer Status],"Active")) | D41: =IF($A41="","",COUNTIFS(tblBilling[Month],DB_Month,tblBilling[Area],$A41)) | E41: =IF($A41="","",SUMIFS(tblBilling[Monthly Fee],tblBilling[Month],DB_Month,tblBilling[Area],$A41)) | F41: =IF($A41="","",SUMIFS(tblBilling[Amount Paid],tblBilling[Month],DB_Month,tblBilling[Area],$A41)) | G41: =IF($A41="","",SUMIFS(tblBilling[Balance],tblBilling[Month],DB_Month,tblBilling[Area],$A41)) | H41: =IF($A41="","",COUNTIFS(tblBilling[Month],DB_Month,tblBilling[Area],$A41,tblBilling[Payment Status],"PAID")) | I41: =IF($A41="","",COUNTIFS(tblBilling[Month],DB_Month,tblBilling[Area],$A41,tblBilling[Payment Status],"PARTIAL")) | J41: =IF($A41="","",COUNTIFS(tblBilling[Month],DB_Month,tblBilling[Area],$A41,tblBilling[Payment Status],"PENDING")) | K41: =IF(OR($A41="",N(E41)=0),"",F41/E41)
A42: =IFERROR(INDEX(tblAreas[Area Name],23)&"","") | B42: =IF($A42="","",COUNTIF(tblCustomers[Area],$A42)) | C42: =IF($A42="","",COUNTIFS(tblCustomers[Area],$A42,tblCustomers[Customer Status],"Active")) | D42: =IF($A42="","",COUNTIFS(tblBilling[Month],DB_Month,tblBilling[Area],$A42)) | E42: =IF($A42="","",SUMIFS(tblBilling[Monthly Fee],tblBilling[Month],DB_Month,tblBilling[Area],$A42)) | F42: =IF($A42="","",SUMIFS(tblBilling[Amount Paid],tblBilling[Month],DB_Month,tblBilling[Area],$A42)) | G42: =IF($A42="","",SUMIFS(tblBilling[Balance],tblBilling[Month],DB_Month,tblBilling[Area],$A42)) | H42: =IF($A42="","",COUNTIFS(tblBilling[Month],DB_Month,tblBilling[Area],$A42,tblBilling[Payment Status],"PAID")) | I42: =IF($A42="","",COUNTIFS(tblBilling[Month],DB_Month,tblBilling[Area],$A42,tblBilling[Payment Status],"PARTIAL")) | J42: =IF($A42="","",COUNTIFS(tblBilling[Month],DB_Month,tblBilling[Area],$A42,tblBilling[Payment Status],"PENDING")) | K42: =IF(OR($A42="",N(E42)=0),"",F42/E42)
...

Sheet CUSTOMERS
A1: CUSTOMER MASTER | M1: ◄ HOME
A2: One row per customer. Grey columns are calculated. Area / Street / Address come from Location Code.
A3: Header colours: dark blue = you type | mid blue = system generated (do not edit) | grey = calculated formula (never type)
A4: Customer ID | B4: Customer Name | C4: Location Code | D4: Area | E4: Street | F4: Address Detail | G4: Full Address | H4: VLAN ID | I4: Package | J4: Package Fee | K4: Fee Override | L4: Monthly Fee | M4: Due Date | N4: Mobile Number | O4: Default Collector ID | P4: Connection Date | Q4: Customer Status | R4: Notes | S4: Created Date | T4: Last Updated | U4: Data Check | V4: Search Match
D5: =IFERROR(INDEX(tblLocations[Area Name],MATCH(tblCustomers[[#This Row],[Location Code]],tblLocations[Location Code],0)),"") | E5: =IFERROR(INDEX(tblLocations[Street Name],MATCH(tblCustomers[[#This Row],[Location Code]],tblLocations[Location Code],0))&"","") | G5: =IFERROR(INDEX(tblLocations[Full Address],MATCH(tblCustomers[[#This Row],[Location Code]],tblLocations[Location Code],0)),"")&IF(tblCustomers[[#This Row],[Address Detail]]="","",", "&tblCustomers[[#This Row],[Address Detail]]) | J5: =IFERROR(INDEX(tblPackages[Default Monthly Fee],MATCH(tblCustomers[[#This Row],[Package]],tblPackages[Package Name],0)),"") | L5: =IF(tblCustomers[[#This Row],[Fee Override]]<>"",tblCustomers[[#This Row],[Fee Override]],tblCustomers[[#This Row],[Package Fee]]) | U5: =TRIM(IF(COUNTIF(tblCustomers[Customer ID],tblCustomers[[#This Row],[Customer ID]])>1,"DUPLICATE CUSTOMER ID. ","")&IF(tblCustomers[[#This Row],[Customer Name]]="","NAME MISSING. ","")&IF(tblCustomers[[#This Row],[Location Code]]="","LOCATION CODE MISSING. ",IF(ISNA(MATCH(tblCustomers[[#This Row],[Location Code]],tblLocations[Location Code],0)),"LOCATION CODE "&tblCustomers[[#This Row],[Location Code]]&" DOES NOT EXIST. ",""))&IF(tblCustomers[[#This Row],[VLAN ID]]="","VLAN ID MISSING. ","")&IF(tblCustomers[[#This Row],[Monthly Fee]]="","MONTHLY FEE MISSING. ","")&IF(tblCustomers[[#This Row],[Due Date]]="","DUE DATE MISSING. ","")&IF(tblCustomers[[#This Row],[Customer Status]]="","STATUS MISSING. ","")&IF(AND(tblCustomers[[#This Row],[Mobile Number]]<>"",COUNTIF(tblCustomers[Mobile Number],tblCustomers[[#This Row],[Mobile Number]])>1),"POSSIBLE DUPLICATE: SAME MOBILE. ","")&IF(AND(tblCustomers[[#This Row],[Customer Name]]<>"",COUNTIFS(tblCustomers[Customer Name],tblCustomers[[#This Row],[Customer Name]],tblCustomers[Location Code],tblCustomers[[#This Row],[Location Code]])>1),"POSSIBLE DUPLICATE: SAME NAME + LOCATION. ","")&IF(AND(tblCustomers[[#This Row],[VLAN ID]]<>"",tblCustomers[[#This Row],[Customer Status]]="Active",COUNTIFS(tblCustomers[VLAN ID],tblCustomers[[#This Row],[VLAN ID]],tblCustomers[Customer Status],"Active")>1),"VLAN USED BY ANOTHER ACTIVE CUSTOMER. ","")) | V5: =IF(CH_SearchText="",0,IF(ISNUMBER(SEARCH(CH_SearchText,CHOOSE(MATCH(CH_SearchType,L_SearchTypes,0),tblCustomers[[#This Row],[Customer ID]],tblCustomers[[#This Row],[Customer Name]],SUBSTITUTE(SUBSTITUTE(tblCustomers[[#This Row],[Mobile Number]],"-","")," ",""),tblCustomers[[#This Row],[VLAN ID]]&"",tblCustomers[[#This Row],[Location Code]],tblCustomers[[#This Row],[Area]],tblCustomers[[#This Row],[Customer ID]]&"|"&tblCustomers[[#This Row],[Customer Name]]&"|"&SUBSTITUTE(tblCustomers[[#This Row],[Mobile Number]],"-","")&"|"&tblCustomers[[#This Row],[VLAN ID]]&"|"&tblCustomers[[#This Row],[Location Code]]&"|"&tblCustomers[[#This Row],[Area]]))),1,0))

Sheet MONTHLY_BILLING
A1: MONTHLY BILLING (ALL MONTHS - HISTORY) | M1: ◄ HOME
A2: One row per customer per month, created by GENERATE NEW MONTH. Never overwritten. Paid / Balance / Status are calculated from PAYMENTS.
A3: Header colours: dark blue = you type | mid blue = system generated (do not edit) | grey = calculated formula (never type)
A4: Billing ID | B4: Month | C4: Month Name | D4: Customer ID | E4: Customer Name | F4: Location Code | G4: Area | H4: Street | I4: Full Address | J4: VLAN ID | K4: Package | L4: Due Date | M4: Monthly Fee | N4: Collector ID | O4: Collector Name | P4: Amount Paid | Q4: Balance | R4: Excess Paid | S4: Payment Status | T4: Overdue | U4: Payments Count | V4: Last Payment Date | W4: Remarks | X4: Created At | Y4: Print Match | Z4: Stmt Match
N5: =IFERROR(INDEX(tblAssignments[Collector ID],MATCH(tblBilling[[#This Row],[Month]]&"|"&tblBilling[[#This Row],[Customer ID]],tblAssignments[Key],0))&"","") | O5: =IF(tblBilling[[#This Row],[Collector ID]]="","Unassigned",IFERROR(INDEX(tblCollectors[Collector Name],MATCH(tblBilling[[#This Row],[Collector ID]],tblCollectors[Collector ID],0)),tblBilling[[#This Row],[Collector ID]])) | P5: =SUMIFS(tblPayments[Amount],tblPayments[Billing ID],tblBilling[[#This Row],[Billing ID]],tblPayments[Voided],"<>Yes") | Q5: =IF(CFG_AllowNegativeBalance="Yes",tblBilling[[#This Row],[Monthly Fee]]-tblBilling[[#This Row],[Amount Paid]],MAX(0,tblBilling[[#This Row],[Monthly Fee]]-tblBilling[[#This Row],[Amount Paid]])) | R5: =MAX(0,tblBilling[[#This Row],[Amount Paid]]-tblBilling[[#This Row],[Monthly Fee]]) | S5: =IF(tblBilling[[#This Row],[Amount Paid]]>=tblBilling[[#This Row],[Monthly Fee]],"PAID",IF(tblBilling[[#This Row],[Amount Paid]]>0,"PARTIAL","PENDING")) | T5: =IF(OR(tblBilling[[#This Row],[Balance]]<=0,tblBilling[[#This Row],[Due Date]]=""),"",IF(TODAY()>DATE(LEFT(tblBilling[[#This Row],[Month]],4),MID(tblBilling[[#This Row],[Month]],6,2),MIN(tblBilling[[#This Row],[Due Date]],DAY(EOMONTH(DATE(LEFT(tblBilling[[#This Row],[Month]],4),MID(tblBilling[[#This Row],[Month]],6,2),1),0))))+CFG_OverdueGraceDays,"OVERDUE","")) | U5: =COUNTIFS(tblPayments[Billing ID],tblBilling[[#This Row],[Billing ID]],tblPayments[Voided],"<>Yes") | V5: =IF(tblBilling[[#This Row],[Payments Count]]=0,"",IFERROR(_xlfn.MAXIFS(tblPayments[Payment Date],tblPayments[Billing ID],tblBilling[[#This Row],[Billing ID]],tblPayments[Voided],"<>Yes"),"")) | Y5: =IF(AND(tblBilling[[#This Row],[Month]]=PC_Month,OR(PC_Area="All",tblBilling[[#This Row],[Area]]=PC_Area),OR(PC_Location="All",tblBilling[[#This Row],[Location Code]]=PC_Location),OR(PC_Collector="All",tblBilling[[#This Row],[Collector Name]]=PC_Collector),OR(PC_DueDate="All",tblBilling[[#This Row],[Due Date]]=PC_DueDate),OR(PC_StatusEff="All",AND(PC_StatusEff="UNPAID",tblBilling[[#This Row],[Balance]]>0),tblBilling[[#This Row],[Payment Status]]=PC_StatusEff,AND(PC_StatusEff="OVERDUE",tblBilling[[#This Row],[Overdue]]="OVERDUE")),OR(PC_Mode<>"Custom Filtered Recovery",PC_CustomCount=0,COUNTIF(PC_CustomIDs,tblBilling[[#This Row],[Customer ID]])>0)),1,0) | Z5: =IF(AND(tblBilling[[#This Row],[Customer ID]]=ST_CustomerID,OR(ST_From="All",tblBilling[[#This Row],[Month]]>=ST_From),OR(ST_To="All",tblBilling[[#This Row],[Month]]<=ST_To)),1,0)

Sheet PAYMENTS
A1: PAYMENT TRANSACTIONS | M1: ◄ HOME
A2: Every payment is a separate row (multiple partial payments allowed). Never delete - set Voided = Yes.
A3: Header colours: dark blue = you type | mid blue = system generated (do not edit) | grey = calculated formula (never type)
A4: Payment ID | B4: Customer ID | C4: Customer Name | D4: Month | E4: Billing ID | F4: Payment Date | G4: Amount | H4: Payment Method | I4: Collector ID | J4: Reference | K4: Remarks | L4: Voided | M4: Void Reason | N4: Created At | O4: Data Check
C5: =IFERROR(INDEX(tblCustomers[Customer Name],MATCH(tblPayments[[#This Row],[Customer ID]],tblCustomers[Customer ID],0)),"CUSTOMER NOT FOUND") | E5: =IF(OR(tblPayments[[#This Row],[Month]]="",tblPayments[[#This Row],[Customer ID]]=""),"",tblPayments[[#This Row],[Month]]&"-"&tblPayments[[#This Row],[Customer ID]]) | O5: =TRIM(IF(AND(tblPayments[[#This Row],[Billing ID]]<>"",ISNA(MATCH(tblPayments[[#This Row],[Billing ID]],tblBilling[Billing ID],0))),"NO BILL FOR THIS CUSTOMER/MONTH. ","")&IF(N(tblPayments[[#This Row],[Amount]])<=0,"AMOUNT MUST BE MORE THAN 0. ","")&IF(COUNTIF(tblPayments[Payment ID],tblPayments[[#This Row],[Payment ID]])>1,"DUPLICATE PAYMENT ID. ","")&IF(tblPayments[[#This Row],[Payment Date]]="","PAYMENT DATE MISSING. ",""))

Sheet PAYMENT_ENTRY
A1: PAYMENT ENTRY | H1: ◄ HOME
A2: Type a Customer ID to see the bill. Recommended: record payments with the menu program (option 'Record payment') - it saves and checks everything automatically.
B4: Customer ID
B5: Month | C5: =CFG_CurrentMonth
B7: Customer Name | C7: =IF(PE_CustomerID="","",IFERROR(INDEX(tblCustomers[Customer Name],MATCH(PE_CustomerID,tblCustomers[Customer ID],0)),"Customer "&PE_CustomerID&" was not found."))
B8: Full Address | C8: =IF(PE_CustomerID="","",IFERROR(INDEX(tblCustomers[Full Address],MATCH(PE_CustomerID,tblCustomers[Customer ID],0)),"Customer "&PE_CustomerID&" was not found."))
B9: VLAN ID | C9: =IF(PE_CustomerID="","",IFERROR(INDEX(tblCustomers[VLAN ID],MATCH(PE_CustomerID,tblCustomers[Customer ID],0)),"Customer "&PE_CustomerID&" was not found."))
B10: Mobile | C10: =IF(PE_CustomerID="","",IFERROR(INDEX(tblCustomers[Mobile Number],MATCH(PE_CustomerID,tblCustomers[Customer ID],0)),"Customer "&PE_CustomerID&" was not found."))
B11: Customer Status | C11: =IF(PE_CustomerID="","",IFERROR(INDEX(tblCustomers[Customer Status],MATCH(PE_CustomerID,tblCustomers[Customer ID],0)),"Customer "&PE_CustomerID&" was not found."))
B12: Bill (this month) | C12: =IF(PE_CustomerID="","",IFERROR(INDEX(tblBilling[Monthly Fee],MATCH(PE_Month&"-"&PE_CustomerID,tblBilling[Billing ID],0)),"No bill for this month"))
B13: Already Paid | C13: =IF(PE_CustomerID="","",IFERROR(INDEX(tblBilling[Amount Paid],MATCH(PE_Month&"-"&PE_CustomerID,tblBilling[Billing ID],0)),"No bill for this month"))
B14: Remaining | C14: =IF(PE_CustomerID="","",IFERROR(INDEX(tblBilling[Balance],MATCH(PE_Month&"-"&PE_CustomerID,tblBilling[Billing ID],0)),"No bill for this month"))
B15: Payment Status | C15: =IF(PE_CustomerID="","",IFERROR(INDEX(tblBilling[Payment Status],MATCH(PE_Month&"-"&PE_CustomerID,tblBilling[Billing ID],0)),"No bill for this month"))
B16: Assigned Collector | C16: =IF(PE_CustomerID="","",IFERROR(INDEX(tblBilling[Collector Name],MATCH(PE_Month&"-"&PE_CustomerID,tblBilling[Billing ID],0)),"No bill for this month"))
B17: Outstanding (all months) | C17: =IF(PE_CustomerID="","",SUMIFS(tblBilling[Balance],tblBilling[Customer ID],PE_CustomerID))
B18: Next Payment ID | C18: ="PAY-"&TEXT(IFERROR(AGGREGATE(14,6,--MID(tblPayments[Payment ID],5,10),1),0)+1,"000000")
B20: HOW TO SAVE A PAYMENT WITHOUT THE MENU PROGRAM
B21: 1. Go to PAYMENTS and type in the first empty row below the table: Payment ID (shown above), Customer ID, Month,
B22: Payment Date, Amount, Payment Method, Collector ID. Set Voided = No.
B23: 2. Amount Paid, Balance and Status in MONTHLY_BILLING update automatically. Several partial payments are allowed.
B24: 3. Never delete a wrong payment - set Voided = Yes and write the reason.
B26: ► Open PAYMENTS
B28: THIS CUSTOMER'S PAYMENTS (latest 20 shown in order entered)
B29: Payment ID | C29: Month | D29: Payment Date | E29: Amount | F29: Method | G29: Collector | H29: Reference | I29: Voided
B30: =IF($K30="","",INDEX(tblPayments[Payment ID],$K30)&"") | C30: =IF($K30="","",INDEX(tblPayments[Month],$K30)&"") | D30: =IF($K30="","",INDEX(tblPayments[Payment Date],$K30)) | E30: =IF($K30="","",INDEX(tblPayments[Amount],$K30)) | F30: =IF($K30="","",INDEX(tblPayments[Payment Method],$K30)&"") | G30: =IF($K30="","",INDEX(tblPayments[Collector ID],$K30)&"") | H30: =IF($K30="","",INDEX(tblPayments[Reference],$K30)&"") | I30: =IF($K30="","",INDEX(tblPayments[Voided],$K30)&"") | K30: =IF(PE_CustomerID="","",IFERROR(MATCH(PE_CustomerID,tblPayments[Customer ID],0),""))
B31: =IF($K31="","",INDEX(tblPayments[Payment ID],$K31)&"") | C31: =IF($K31="","",INDEX(tblPayments[Month],$K31)&"") | D31: =IF($K31="","",INDEX(tblPayments[Payment Date],$K31)) | E31: =IF($K31="","",INDEX(tblPayments[Amount],$K31)) | F31: =IF($K31="","",INDEX(tblPayments[Payment Method],$K31)&"") | G31: =IF($K31="","",INDEX(tblPayments[Collector ID],$K31)&"") | H31: =IF($K31="","",INDEX(tblPayments[Reference],$K31)&"") | I31: =IF($K31="","",INDEX(tblPayments[Voided],$K31)&"") | K31: =IF(K30="","",IFERROR(K30+MATCH(PE_CustomerID,INDEX(tblPayments[Customer ID],K30+1):INDEX(tblPayments[Customer ID],ROWS(tblPayments[Customer ID])),0),""))
B32: =IF($K32="","",INDEX(tblPayments[Payment ID],$K32)&"") | C32: =IF($K32="","",INDEX(tblPayments[Month],$K32)&"") | D32: =IF($K32="","",INDEX(tblPayments[Payment Date],$K32)) | E32: =IF($K32="","",INDEX(tblPayments[Amount],$K32)) | F32: =IF($K32="","",INDEX(tblPayments[Payment Method],$K32)&"") | G32: =IF($K32="","",INDEX(tblPayments[Collector ID],$K32)&"") | H32: =IF($K32="","",INDEX(tblPayments[Reference],$K32)&"") | I32: =IF($K32="","",INDEX(tblPayments[Voided],$K32)&"") | K32: =IF(K31="","",IFERROR(K31+MATCH(PE_CustomerID,INDEX(tblPayments[Customer ID],K31+1):INDEX(tblPayments[Customer ID],ROWS(tblPayments[Customer ID])),0),""))
B33: =IF($K33="","",INDEX(tblPayments[Payment ID],$K33)&"") | C33: =IF($K33="","",INDEX(tblPayments[Month],$K33)&"") | D33: =IF($K33="","",INDEX(tblPayments[Payment Date],$K33)) | E33: =IF($K33="","",INDEX(tblPayments[Amount],$K33)) | F33: =IF($K33="","",INDEX(tblPayments[Payment Method],$K33)&"") | G33: =IF($K33="","",INDEX(tblPayments[Collector ID],$K33)&"") | H33: =IF($K33="","",INDEX(tblPayments[Reference],$K33)&"") | I33: =IF($K33="","",INDEX(tblPayments[Voided],$K33)&"") | K33: =IF(K32="","",IFERROR(K32+MATCH(PE_CustomerID,INDEX(tblPayments[Customer ID],K32+1):INDEX(tblPayments[Customer ID],ROWS(tblPayments[Customer ID])),0),""))
B34: =IF($K34="","",INDEX(tblPayments[Payment ID],$K34)&"") | C34: =IF($K34="","",INDEX(tblPayments[Month],$K34)&"") | D34: =IF($K34="","",INDEX(tblPayments[Payment Date],$K34)) | E34: =IF($K34="","",INDEX(tblPayments[Amount],$K34)) | F34: =IF($K34="","",INDEX(tblPayments[Payment Method],$K34)&"") | G34: =IF($K34="","",INDEX(tblPayments[Collector ID],$K34)&"") | H34: =IF($K34="","",INDEX(tblPayments[Reference],$K34)&"") | I34: =IF($K34="","",INDEX(tblPayments[Voided],$K34)&"") | K34: =IF(K33="","",IFERROR(K33+MATCH(PE_CustomerID,INDEX(tblPayments[Customer ID],K33+1):INDEX(tblPayments[Customer ID],ROWS(tblPayments[Customer ID])),0),""))
B35: =IF($K35="","",INDEX(tblPayments[Payment ID],$K35)&"") | C35: =IF($K35="","",INDEX(tblPayments[Month],$K35)&"") | D35: =IF($K35="","",INDEX(tblPayments[Payment Date],$K35)) | E35: =IF($K35="","",INDEX(tblPayments[Amount],$K35)) | F35: =IF($K35="","",INDEX(tblPayments[Payment Method],$K35)&"") | G35: =IF($K35="","",INDEX(tblPayments[Collector ID],$K35)&"") | H35: =IF($K35="","",INDEX(tblPayments[Reference],$K35)&"") | I35: =IF($K35="","",INDEX(tblPayments[Voided],$K35)&"") | K35: =IF(K34="","",IFERROR(K34+MATCH(PE_CustomerID,INDEX(tblPayments[Customer ID],K34+1):INDEX(tblPayments[Customer ID],ROWS(tblPayments[Customer ID])),0),""))
B36: =IF($K36="","",INDEX(tblPayments[Payment ID],$K36)&"") | C36: =IF($K36="","",INDEX(tblPayments[Month],$K36)&"") | D36: =IF($K36="","",INDEX(tblPayments[Payment Date],$K36)) | E36: =IF($K36="","",INDEX(tblPayments[Amount],$K36)) | F36: =IF($K36="","",INDEX(tblPayments[Payment Method],$K36)&"") | G36: =IF($K36="","",INDEX(tblPayments[Collector ID],$K36)&"") | H36: =IF($K36="","",INDEX(tblPayments[Reference],$K36)&"") | I36: =IF($K36="","",INDEX(tblPayments[Voided],$K36)&"") | K36: =IF(K35="","",IFERROR(K35+MATCH(PE_CustomerID,INDEX(tblPayments[Customer ID],K35+1):INDEX(tblPayments[Customer ID],ROWS(tblPayments[Customer ID])),0),""))
B37: =IF($K37="","",INDEX(tblPayments[Payment ID],$K37)&"") | C37: =IF($K37="","",INDEX(tblPayments[Month],$K37)&"") | D37: =IF($K37="","",INDEX(tblPayments[Payment Date],$K37)) | E37: =IF($K37="","",INDEX(tblPayments[Amount],$K37)) | F37: =IF($K37="","",INDEX(tblPayments[Payment Method],$K37)&"") | G37: =IF($K37="","",INDEX(tblPayments[Collector ID],$K37)&"") | H37: =IF($K37="","",INDEX(tblPayments[Reference],$K37)&"") | I37: =IF($K37="","",INDEX(tblPayments[Voided],$K37)&"") | K37: =IF(K36="","",IFERROR(K36+MATCH(PE_CustomerID,INDEX(tblPayments[Customer ID],K36+1):INDEX(tblPayments[Customer ID],ROWS(tblPayments[Customer ID])),0),""))
B38: =IF($K38="","",INDEX(tblPayments[Payment ID],$K38)&"") | C38: =IF($K38="","",INDEX(tblPayments[Month],$K38)&"") | D38: =IF($K38="","",INDEX(tblPayments[Payment Date],$K38)) | E38: =IF($K38="","",INDEX(tblPayments[Amount],$K38)) | F38: =IF($K38="","",INDEX(tblPayments[Payment Method],$K38)&"") | G38: =IF($K38="","",INDEX(tblPayments[Collector ID],$K38)&"") | H38: =IF($K38="","",INDEX(tblPayments[Reference],$K38)&"") | I38: =IF($K38="","",INDEX(tblPayments[Voided],$K38)&"") | K38: =IF(K37="","",IFERROR(K37+MATCH(PE_CustomerID,INDEX(tblPayments[Customer ID],K37+1):INDEX(tblPayments[Customer ID],ROWS(tblPayments[Customer ID])),0),""))
B39: =IF($K39="","",INDEX(tblPayments[Payment ID],$K39)&"") | C39: =IF($K39="","",INDEX(tblPayments[Month],$K39)&"") | D39: =IF($K39="","",INDEX(tblPayments[Payment Date],$K39)) | E39: =IF($K39="","",INDEX(tblPayments[Amount],$K39)) | F39: =IF($K39="","",INDEX(tblPayments[Payment Method],$K39)&"") | G39: =IF($K39="","",INDEX(tblPayments[Collector ID],$K39)&"") | H39: =IF($K39="","",INDEX(tblPayments[Reference],$K39)&"") | I39: =IF($K39="","",INDEX(tblPayments[Voided],$K39)&"") | K39: =IF(K38="","",IFERROR(K38+MATCH(PE_CustomerID,INDEX(tblPayments[Customer ID],K38+1):INDEX(tblPayments[Customer ID],ROWS(tblPayments[Customer ID])),0),""))
B40: =IF($K40="","",INDEX(tblPayments[Payment ID],$K40)&"") | C40: =IF($K40="","",INDEX(tblPayments[Month],$K40)&"") | D40: =IF($K40="","",INDEX(tblPayments[Payment Date],$K40)) | E40: =IF($K40="","",INDEX(tblPayments[Amount],$K40)) | F40: =IF($K40="","",INDEX(tblPayments[Payment Method],$K40)&"") | G40: =IF($K40="","",INDEX(tblPayments[Collector ID],$K40)&"") | H40: =IF($K40="","",INDEX(tblPayments[Reference],$K40)&"") | I40: =IF($K40="","",INDEX(tblPayments[Voided],$K40)&"") | K40: =IF(K39="","",IFERROR(K39+MATCH(PE_CustomerID,INDEX(tblPayments[Customer ID],K39+1):INDEX(tblPayments[Customer ID],ROWS(tblPayments[Customer ID])),0),""))
B41: =IF($K41="","",INDEX(tblPayments[Payment ID],$K41)&"") | C41: =IF($K41="","",INDEX(tblPayments[Month],$K41)&"") | D41: =IF($K41="","",INDEX(tblPayments[Payment Date],$K41)) | E41: =IF($K41="","",INDEX(tblPayments[Amount],$K41)) | F41: =IF($K41="","",INDEX(tblPayments[Payment Method],$K41)&"") | G41: =IF($K41="","",INDEX(tblPayments[Collector ID],$K41)&"") | H41: =IF($K41="","",INDEX(tblPayments[Reference],$K41)&"") | I41: =IF($K41="","",INDEX(tblPayments[Voided],$K41)&"") | K41: =IF(K40="","",IFERROR(K40+MATCH(PE_CustomerID,INDEX(tblPayments[Customer ID],K40+1):INDEX(tblPayments[Customer ID],ROWS(tblPayments[Customer ID])),0),""))
B42: =IF($K42="","",INDEX(tblPayments[Payment ID],$K42)&"") | C42: =IF($K42="","",INDEX(tblPayments[Month],$K42)&"") | D42: =IF($K42="","",INDEX(tblPayments[Payment Date],$K42)) | E42: =IF($K42="","",INDEX(tblPayments[Amount],$K42)) | F42: =IF($K42="","",INDEX(tblPayments[Payment Method],$K42)&"") | G42: =IF($K42="","",INDEX(tblPayments[Collector ID],$K42)&"") | H42: =IF($K42="","",INDEX(tblPayments[Reference],$K42)&"") | I42: =IF($K42="","",INDEX(tblPayments[Voided],$K42)&"") | K42: =IF(K41="","",IFERROR(K41+MATCH(PE_CustomerID,INDEX(tblPayments[Customer ID],K41+1):INDEX(tblPayments[Customer ID],ROWS(tblPayments[Customer ID])),0),""))
... B49: =IF($K49="","",INDEX(tblPayments[Payment ID],$K49)&"") | C49: =IF($K49="","",INDEX(tblPayments[Month],$K49)&"") | D49: =IF($K49="","",INDEX(tblPayments[Payment Date],$K49)) | E49: =IF($K49="","",INDEX(tblPayments[Amount],$K49)) | F49: =IF($K49="","",INDEX(tblPayments[Payment Method],$K49)&"") | G49: =IF($K49="","",INDEX(tblPayments[Collector ID],$K49)&"") | H49: =IF($K49="","",INDEX(tblPayments[Reference],$K49)&"") | I49: =IF($K49="","",INDEX(tblPayments[Voided],$K49)&"") | K49: =IF(K48="","",IFERROR(K48+MATCH(PE_CustomerID,INDEX(tblPayments[Customer ID],K48+1):INDEX(tblPayments[Customer ID],ROWS(tblPayments[Customer ID])),0),""))

Sheet PRINT_CENTER
A1: PRINT CENTER - RECOVERY LISTS | H1: ◄ HOME
A2: 1) Choose filters in the yellow cells 2) Check the preview count 3) Open PRINT SHEET and print (Ctrl+P).
F3: Custom Customer IDs | G3: Count
B4: Print Mode | C4: Area-wise Recovery | G4: =COUNTIF(PC_CustomIDs,"?*")
B5: Month | C5: =CFG_CurrentMonth | D5: =IFERROR(TEXT(DATE(LEFT(PC_Month,4),MID(PC_Month,6,2),1),"mmmm yyyy"),"")
B6: Area | C6: All
B7: Location Code / Street | C7: All | D7: =IF(PC_Location="All","",IFERROR(INDEX(tblLocations[Full Address],MATCH(PC_Location,tblLocations[Location Code],0)),"Location Code does not exist"))
B8: Collector | C8: All
B9: Payment Status | C9: All | D9: UNPAID = Pending + Partial (everyone who still owes money)
B10: Due Date (day) | C10: All
B12: Effective Status Filter | C12: =IF(AND(PC_Mode="Pending Recovery",PC_Status="All"),"UNPAID",IF(AND(PC_Mode="Partial Payment Recovery",PC_Status="All"),"PARTIAL",PC_Status))
B13: Customers in this list | C13: =SUM(tblBilling[Print Match])
B14: List Title | C14: =TRIM(IF(PC_Location<>"All",IFERROR(INDEX(tblLocations[Full Address],MATCH(PC_Location,tblLocations[Location Code],0)),PC_Location),IF(PC_Area<>"All",PC_Area,"All Areas"))&" "&IFERROR(INDEX(L_PrintStatusLabels,MATCH(PC_StatusEff,L_PrintStatuses,0)),"")&" Recovery List"&IF(PC_Collector<>"All"," - "&PC_Collector,"")&IF(PC_DueDate<>"All"," - Due "&PC_DueDate,""))
B15: Total Billing | C15: =SUMIFS(tblBilling[Monthly Fee],tblBilling[Print Match],1)
B16: Total Recovered | C16: =SUMIFS(tblBilling[Amount Paid],tblBilling[Print Match],1)
B17: Total Pending | C17: =SUMIFS(tblBilling[Balance],tblBilling[Print Match],1)
B18: Message | C18: =IF(COUNTIF(tblBilling[Month],PC_Month)=0,"No billing exists for "&PC_Month&". Generate the month first.",IF(PC_Count>500,"More than 500 customers - narrow the filters or use the menu program (Print recovery list PDF).",IF(PC_Count=0,"No customers match these filters.","Ready to print.")))
C20: ► OPEN PRINT SHEET (English)
C21: ► OPEN PRINT SHEET (Urdu / RTL)
C22: ="Print Language in SETTINGS: "&CFG_PrintLanguage
B24: PRINT MODES (presets)
B25: Area-wise Recovery | C25: Choose Area, keep Location = All.
B26: Street-wise Recovery | C26: Choose Location Code e.g. A1 (Arif Town, Gali 1).
B27: Collector-wise Recovery | C27: Choose Collector (uses RECOVERY_ASSIGNMENTS).
B28: Due-Date-wise Recovery | C28: Choose Due Date (day of month).
B29: Pending Recovery | C29: Status All is treated as UNPAID (pending + partial).
B30: Partial Payment Recovery | C30: Status All is treated as PARTIAL.
B31: Custom Filtered Recovery | C31: Type Customer IDs in column F; only those customers are listed (other filters still apply).

Sheet PRINT_SHEET
A1: =CFG_CompanyName | Z1: =MIN(PC_Count,500)+9+7
A2: =CFG_Tagline
A3: MONTHLY RECOVERY SHEET
A4: =PC_Title
A5: Area: | C5: =PC_Area | D5: Location/Street: | E5: =IF(PC_Location="All","All",PC_Location&" - "&IFERROR(INDEX(tblLocations[Full Address],MATCH(PC_Location,tblLocations[Location Code],0)),"")) | H5: Month: | I5: =IFERROR(TEXT(DATE(LEFT(PC_Month,4),MID(PC_Month,6,2),1),"mmmm yyyy"),PC_Month) | J5: Collector: | K5: =PC_Collector
A6: Total Customers: | C6: =PC_Count | D6: Total Billing: | E6: =CFG_CurrencySymbol&" "&TEXT(PC_TotalFee,"#,##0") | H6: Recovered: | I6: =CFG_CurrencySymbol&" "&TEXT(PC_TotalPaid,"#,##0") | J6: Pending: | K6: =CFG_CurrencySymbol&" "&TEXT(PC_TotalBalance,"#,##0")
A7: Status: | C7: =PC_StatusEff | D7: Printed: | E7: =TODAY()
A9: # | B9: Customer ID | C9: Customer Name | D9: Address | E9: VLAN ID | F9: Due Date | G9: Monthly Fee | H9: Amount Paid | I9: Balance | J9: Status | K9: Collection Date | L9: Collector
A10: =IF($N10="","",ROW()-9) | B10: =IF($N10<>"",INDEX(tblBilling[Customer ID],$N10),"") | C10: =IF($N10<>"",INDEX(tblBilling[Customer Name],$N10),CHOOSE(MIN(MAX($O10,0),7)+1,"","TOTAL","","Total Customers: "&PC_Count,"Total Recovered: "&CFG_CurrencySymbol&" "&TEXT(PC_TotalPaid,"#,##0"),"","Collector Signature: ____________","")) | D10: =IF($N10<>"",INDEX(tblBilling[Full Address],$N10),CHOOSE(MIN(MAX($O10,0),7)+1,"","","","Total Billing: "&CFG_CurrencySymbol&" "&TEXT(PC_TotalFee,"#,##0"),"Total Pending: "&CFG_CurrencySymbol&" "&TEXT(PC_TotalBalance,"#,##0"),"","Office Verification: ____________","")) | E10: =IF($N10<>"",INDEX(tblBilling[VLAN ID],$N10),"") | F10: =IF($N10<>"",INDEX(tblBilling[Due Date],$N10),"") | G10: =IF($N10<>"",INDEX(tblBilling[Monthly Fee],$N10),IF($O10=1,PC_TotalFee,"")) | H10: =IF($N10<>"",INDEX(tblBilling[Amount Paid],$N10),IF($O10=1,PC_TotalPaid,"")) | I10: =IF($N10<>"",INDEX(tblBilling[Balance],$N10),IF($O10=1,PC_TotalBalance,"")) | J10: =IF($N10<>"",INDEX(tblBilling[Payment Status],$N10),"") | K10: =IF($N10<>"",IF(INDEX(tblBilling[Last Payment Date],$N10)="","",INDEX(tblBilling[Last Payment Date],$N10)),"") | L10: =IF($N10<>"",INDEX(tblBilling[Collector Name],$N10),"") | N10: =IFERROR(MATCH(1,tblBilling[Print Match],0),"") | O10: =ROW()-9-MIN(PC_Count,500)
A11: =IF($N11="","",ROW()-9) | B11: =IF($N11<>"",INDEX(tblBilling[Customer ID],$N11),"") | C11: =IF($N11<>"",INDEX(tblBilling[Customer Name],$N11),CHOOSE(MIN(MAX($O11,0),7)+1,"","TOTAL","","Total Customers: "&PC_Count,"Total Recovered: "&CFG_CurrencySymbol&" "&TEXT(PC_TotalPaid,"#,##0"),"","Collector Signature: ____________","")) | D11: =IF($N11<>"",INDEX(tblBilling[Full Address],$N11),CHOOSE(MIN(MAX($O11,0),7)+1,"","","","Total Billing: "&CFG_CurrencySymbol&" "&TEXT(PC_TotalFee,"#,##0"),"Total Pending: "&CFG_CurrencySymbol&" "&TEXT(PC_TotalBalance,"#,##0"),"","Office Verification: ____________","")) | E11: =IF($N11<>"",INDEX(tblBilling[VLAN ID],$N11),"") | F11: =IF($N11<>"",INDEX(tblBilling[Due Date],$N11),"") | G11: =IF($N11<>"",INDEX(tblBilling[Monthly Fee],$N11),IF($O11=1,PC_TotalFee,"")) | H11: =IF($N11<>"",INDEX(tblBilling[Amount Paid],$N11),IF($O11=1,PC_TotalPaid,"")) | I11: =IF($N11<>"",INDEX(tblBilling[Balance],$N11),IF($O11=1,PC_TotalBalance,"")) | J11: =IF($N11<>"",INDEX(tblBilling[Payment Status],$N11),"") | K11: =IF($N11<>"",IF(INDEX(tblBilling[Last Payment Date],$N11)="","",INDEX(tblBilling[Last Payment Date],$N11)),"") | L11: =IF($N11<>"",INDEX(tblBilling[Collector Name],$N11),"") | N11: =IF(N10="","",IFERROR(N10+MATCH(1,INDEX(tblBilling[Print Match],N10+1):INDEX(tblBilling[Print Match],ROWS(tblBilling[Print Match])),0),"")) | O11: =ROW()-9-MIN(PC_Count,500)
A12: =IF($N12="","",ROW()-9) | B12: =IF($N12<>"",INDEX(tblBilling[Customer ID],$N12),"") | C12: =IF($N12<>"",INDEX(tblBilling[Customer Name],$N12),CHOOSE(MIN(MAX($O12,0),7)+1,"","TOTAL","","Total Customers: "&PC_Count,"Total Recovered: "&CFG_CurrencySymbol&" "&TEXT(PC_TotalPaid,"#,##0"),"","Collector Signature: ____________","")) | D12: =IF($N12<>"",INDEX(tblBilling[Full Address],$N12),CHOOSE(MIN(MAX($O12,0),7)+1,"","","","Total Billing: "&CFG_CurrencySymbol&" "&TEXT(PC_TotalFee,"#,##0"),"Total Pending: "&CFG_CurrencySymbol&" "&TEXT(PC_TotalBalance,"#,##0"),"","Office Verification: ____________","")) | E12: =IF($N12<>"",INDEX(tblBilling[VLAN ID],$N12),"") | F12: =IF($N12<>"",INDEX(tblBilling[Due Date],$N12),"") | G12: =IF($N12<>"",INDEX(tblBilling[Monthly Fee],$N12),IF($O12=1,PC_TotalFee,"")) | H12: =IF($N12<>"",INDEX(tblBilling[Amount Paid],$N12),IF($O12=1,PC_TotalPaid,"")) | I12: =IF($N12<>"",INDEX(tblBilling[Balance],$N12),IF($O12=1,PC_TotalBalance,"")) | J12: =IF($N12<>"",INDEX(tblBilling[Payment Status],$N12),"") | K12: =IF($N12<>"",IF(INDEX(tblBilling[Last Payment Date],$N12)="","",INDEX(tblBilling[Last Payment Date],$N12)),"") | L12: =IF($N12<>"",INDEX(tblBilling[Collector Name],$N12),"") | N12: =IF(N11="","",IFERROR(N11+MATCH(1,INDEX(tblBilling[Print Match],N11+1):INDEX(tblBilling[Print Match],ROWS(tblBilling[Print Match])),0),"")) | O12: =ROW()-9-MIN(PC_Count,500)
